Workbook

Sheet README
A1: CLARTÉ360 — TABLEUR MAÎTRE PIP RIASEC
A2: V0.4 — Revue de contextualisation des 120 items + journal de recette L1 | formulations source conservées | exemples distincts du scoring
A4: Champ | B4: Valeur | D4: Mode d’emploi
A5: Nom | B5: CLARTE360_PIP_RIASEC_TABLEUR_MAITRE | D5: 1. Rédiger les items dans QUESTIONS sans modifier les IDs.
A6: Version tableur | B6: 0.4 | D6: 2. Passer les risques/biais de A_EVALUER à FAIBLE/MOYEN/ELEVE après revue.
A7: Statut | B7: BANQUE EXPÉRIMENTALE QUALIFIÉE — 120 items au statut PILOTE ; validation empirique à poursuivre | D7: 3. Changer le statut BROUILLON → REVU → PILOTE → ACTIF selon validation.
A8: Date | B8: 10/09/2026 | D8: 4. Contrôler PARAMETRES : tous les contrôles critiques doivent être OK avant export.
A9: Référentiel méthodologique | B9: REFERENTIEL_METHODOLOGIQUE_PIP_RIASEC_CLARTE360_V1_0.docx | D9: 5. L’application utilisera un export JSON/versionné ; le classeur reste la source métier.
A10: CDC | B10: CDC_PIP_RIASEC_CLARTE360_ONET_V1_4.docx | D10: 6. O*NET est appelé via API officielle ; seule la configuration non secrète figure dans ONET_CONFIG.
A11: Banque cible expérimentale | B11: 120 emplacements candidats : 20 par dimension, 4 par facette | D11: 7. La formulation source reste inchangée tant qu’une décision méthodologique explicite n’est pas prise.
A12: Version finale visée | B12: 60 à 72 items après validation progressive | D12: 8. Les exemples de contextualisation sont gérés dans CONTEXTUALISATION et ne participent jamais au scoring.
A13: Scoring PIP | B13: Réponse 1–5, moyenne par dimension, indice = 25 × (moyenne − 1) | D13: 9. Toute modification d’exemple doit être revue pour hybridité, désirabilité et familiarité sectorielle.
A14: O*NET | B14: Instrument externe distinct ; cible d’intégration via O*NET Web Services API. Aucun item O*NET ni clé API dans ce classeur. | D14: 10. Les anomalies issues de la recette réelle sont suivies dans RECETTE_L1.
A15: Sécurité | B15: Classeur et exports côté serveur / dépôt privé. Jamais exposer mapping, scoring ou banque complète au navigateur.
A16: Règle de source de vérité | B16: Le tableur maître est éditable ; l’application consomme un export contrôlé/versionné et ne devient pas une seconde source de vérité.
A19: Sources externes de référence
A20: https://www.onetcenter.org/IP.html
A21: https://services.onetcenter.org/
A22: https://www.onetcenter.org/license_tools.html
A23: https://www.onetcenter.org/reports/IP_Manual.html
A24: https://www.onetcenter.org/reports/Voc_Interests.html

Sheet BANQUE_72_V0.5
A1: ordre | B1: item_id_source | C1: item_version | D1: bank_version | E1: dimension | F1: facette | G1: bloc | H1: formulation_v0_4 | I1: formulation_v0_5_concrete | J1: decision | K1: justification_selection | L1: risque_hybridite | M1: risque_desirabilite | N1: risque_familiarite_sectorielle
A2: 1 | B2: PIP-ACT-R-R1-001 | C2: 0.5 | D2: PIP-BANK-0.4 | E2: R | F2: R1 | G2: ACT | H2: Assembler des éléments pour fabriquer un objet fonctionnel. | I2: Assembler les pièces d’un petit meuble ou d’un support pour qu’il soit solide et utilisable. | J2: RETENU | K2: Couverture de facette + activité observable ; priorité ACT, complétée par SIT à faible risque. | L2: FAIBLE | M2: FAIBLE | N2: MOYEN
A3: 2 | B3: PIP-ACT-R-R1-002 | C3: 0.5 | D3: PIP-BANK-0.4 | E3: R | F3: R1 | G3: ACT | H3: Transformer une matière ou un matériau pour lui donner une forme utile. | I3: Travailler du bois, du métal ou un autre matériau pour obtenir une pièce ayant une fonction précise. | J3: RETENU | K3: Couverture de facette + activité observable ; priorité ACT, complétée par SIT à faible risque. | L3: FAIBLE | M3: FAIBLE | N3: MOYEN
A4: 3 | B4: PIP-SIT-R-R1-003 | C4: 0.5 | D4: PIP-BANK-0.4 | E4: R | F4: R1 | G4: SIT | H4: Prendre en charge la réalisation concrète d’un objet ou d’une structure à partir d’éléments séparés. | I4: À partir de pièces séparées, réaliser concrètement une étagère, un présentoir ou une petite structure. | J4: RETENU | K4: Couverture de facette + activité observable ; priorité ACT, complétée par SIT à faible risque. | L4: FAIBLE | M4: FAIBLE | N4: MOYEN
A5: 4 | B5: PIP-ACT-R-R2-005 | C5: 0.5 | D5: PIP-BANK-0.4 | E5: R | F5: R2 | G5: ACT | H5: Installer un équipement pour qu’il soit prêt à fonctionner. | I5: Installer un poste de travail, un appareil ou un équipement puis vérifier qu’il fonctionne. | J5: RETENU | K5: Couverture de facette + activité observable ; priorité ACT, complétée par SIT à faible risque. | L5: FAIBLE | M5: FAIBLE | N5: MOYEN
A6: 5 | B6: PIP-ACT-R-R2-006 | C6: 0.5 | D6: PIP-BANK-0.4 | E6: R | F6: R2 | G6: ACT | H6: Réparer un matériel qui ne fonctionne plus correctement. | I6: Rechercher la panne d’un appareil simple puis intervenir concrètement pour le remettre en service. | J6: RETENU | K6: Couverture de facette + activité observable ; priorité ACT, complétée par SIT à faible risque. | L6: MOYEN | M6: FAIBLE | N6: MOYEN
A7: 6 | B7: PIP-ACT-R-R3-009 | C7: 0.5 | D7: PIP-BANK-0.4 | E7: R | F7: R3 | G7: ACT | H7: Utiliser des outils pour réaliser une tâche concrète avec précision. | I7: Utiliser des outils de mesure et des outils manuels pour réaliser un montage avec précision. | J7: RETENU | K7: Couverture de facette + activité observable ; priorité ACT, complétée par SIT à faible risque. | L7: FAIBLE | M7: FAIBLE | N7: MOYEN
A8: 7 | B8: PIP-ACT-R-R3-010 | C8: 0.5 | D8: PIP-BANK-0.4 | E8: R | F8: R3 | G8: ACT | H8: Piloter ou régler une machine pour obtenir le résultat attendu. | I8: Régler une machine ou un équipement pour obtenir une dimension, une forme ou un résultat précis. | J8: RETENU | K8: Couverture de facette + activité observable ; priorité ACT, complétée par SIT à faible risque. | L8: FAIBLE | M8: FAIBLE | N8: MOYEN
A9: 8 | B9: PIP-SIT-R-R3-011 | C9: 0.5 | D9: PIP-BANK-0.4 | E9: R | F9: R3 | G9: SIT | H9: Prendre en charge une tâche qui nécessite de manipuler directement un appareil ou un équipement. | I9: Réaliser une opération qui demande de manipuler directement un appareil, une machine ou un instrument. | J9: RETENU | K9: Couverture de facette + activité observable ; priorité ACT, complétée par SIT à faible risque. | L9: FAIBLE | M9: FAIBLE | N9: MOYEN
A10: 9 | B10: PIP-ACT-R-R4-013 | C10: 0.5 | D10: PIP-BANK-0.4 | E10: R | F10: R4 | G10: ACT | H10: Se rendre sur différents sites pour intervenir directement sur le terrain. | I10: Se déplacer sur plusieurs sites pour constater une situation et intervenir directement sur place. | J10: RETENU | K10: Couverture de facette + activité observable ; priorité ACT, complétée par SIT à faible risque. | L10: FAIBLE | M10: FAIBLE | N10: MOYEN
A11: 10 | B11: PIP-ACT-R-R4-014 | C11: 0.5 | D11: PIP-BANK-0.4 | E11: R | F11: R4 | G11: ACT | H11: Réaliser une activité professionnelle principalement en extérieur. | I11: Passer l’essentiel de sa journée de travail dehors, sur un chantier, un site naturel ou un espace extérieur. | J11: RETENU | K11: Couverture de facette + activité observable ; priorité ACT, complétée par SIT à faible risque. | L11: FAIBLE | M11: FAIBLE | N11: MOYEN
A12: 11 | B12: PIP-ACT-R-R5-017 | C12: 0.5 | D12: PIP-BANK-0.4 | E12: R | F12: R5 | G12: ACT | H12: S’occuper concrètement de plantes ou d’animaux dans le cadre du travail. | I12: S’occuper concrètement de cultures, de plantes ou d’animaux : nourrir, entretenir, surveiller leur état. | J12: RETENU | K12: Couverture de facette + activité observable ; priorité ACT, complétée par SIT à faible risque. | L12: MOYEN | M12: FAIBLE | N12: MOYEN
A13: 12 | B13: PIP-ACT-R-R5-018 | C13: 0.5 | D13: PIP-BANK-0.4 | E13: R | F13: R5 | G13: ACT | H13: Manipuler des matériaux ou des produits pour réaliser une tâche physique utile. | I13: Manipuler des matériaux, déplacer des éléments ou préparer physiquement des produits pour réaliser une opération utile. | J13: RETENU | K13: Couverture de facette + activité observable ; priorité ACT, complétée par SIT à faible risque. | L13: FAIBLE | M13: FAIBLE | N13: MOYEN
... A73: 72 | B73: PIP-ACT-C-C5-018 | C73: 0.5 | D73: PIP-BANK-0.4 | E73: C | F73: C5 | G73: ACT | H73: Planifier et suivre des échéances pour que plusieurs opérations soient réalisées au bon moment. | I73: Planifier plusieurs échéances et vérifier régulièrement que les opérations prévues sont réalisées au bon moment. | J73: RETENU | K73: Couverture de facette + activité observable ; priorité ACT, complétée par SIT à faible risque. | L73: MOYEN | M73: MOYEN | N73: FAIBLE

Sheet REVUE_120_V0.5
A1: item_id | B1: dimension | C1: facette | D1: bloc | E1: formulation_v0_4 | F1: exemple_v0_4 | G1: niveau_concretude | H1: ambiguite_chevauchement | I1: pertinence_professionnelle | J1: decision_v0_5 | K1: formulation_v0_5_si_retenu | L1: motif | M1: bank_version_sortie
A2: PIP-ACT-R-R1-001 | B2: R | C2: R1 | D2: ACT | E2: Assembler des éléments pour fabriquer un objet fonctionnel. | F2: Assembler les pièces d’un petit meuble ou d’un support pour qu’il soit solide et utilisable. | G2: MOYENNE | H2: FAIBLE | I2: FORTE | J2: MAINTIEN_REECRIT | K2: Assembler les pièces d’un petit meuble ou d’un support pour qu’il soit solide et utilisable. | L2: Retenu pour couverture de facette et formulation rendue directement concrète. | M2: PIP-BANK-0.4
A3: PIP-ACT-R-R1-002 | B3: R | C3: R1 | D3: ACT | E3: Transformer une matière ou un matériau pour lui donner une forme utile. | F3: Travailler du bois, du métal ou un autre matériau pour obtenir une pièce ayant une fonction précise. | G3: MOYENNE | H3: FAIBLE | I3: FORTE | J3: MAINTIEN_REECRIT | K3: Travailler du bois, du métal ou un autre matériau pour obtenir une pièce ayant une fonction précise. | L3: Retenu pour couverture de facette et formulation rendue directement concrète. | M3: PIP-BANK-0.4
A4: PIP-SIT-R-R1-003 | B4: R | C4: R1 | D4: SIT | E4: Prendre en charge la réalisation concrète d’un objet ou d’une structure à partir d’éléments séparés. | F4: À partir de pièces séparées, réaliser concrètement une étagère, un présentoir ou une petite structure. | G4: FAIBLE_A_MOYENNE | H4: FAIBLE | I4: FORTE | J4: MAINTIEN_REECRIT | K4: À partir de pièces séparées, réaliser concrètement une étagère, un présentoir ou une petite structure. | L4: Retenu pour couverture de facette et formulation rendue directement concrète. | M4: PIP-BANK-0.4
A5: PIP-ENV-R-R1-004 | B5: R | C5: R1 | D5: ENV | E5: Travailler dans un contexte où l’on voit directement le résultat matériel de ce que l’on fabrique ou transforme. | F5: Évoluer dans un atelier ou un espace de fabrication où l’on voit physiquement ce qui a été produit. | G5: FAIBLE_A_MOYENNE | H5: FAIBLE | I5: MOYENNE | J5: RETRAIT_BANQUE72 | L5: Historique conservé ; item non nécessaire pour atteindre 12/dimension et ≥2/facette. | M5: PIP-BANK-0.3
A6: PIP-ACT-R-R2-005 | B6: R | C6: R2 | D6: ACT | E6: Installer un équipement pour qu’il soit prêt à fonctionner. | F6: Installer un poste de travail, un appareil ou un équipement puis vérifier qu’il fonctionne. | G6: MOYENNE | H6: FAIBLE | I6: FORTE | J6: MAINTIEN_REECRIT | K6: Installer un poste de travail, un appareil ou un équipement puis vérifier qu’il fonctionne. | L6: Retenu pour couverture de facette et formulation rendue directement concrète. | M6: PIP-BANK-0.4
A7: PIP-ACT-R-R2-006 | B7: R | C7: R2 | D7: ACT | E7: Réparer un matériel qui ne fonctionne plus correctement. | F7: Rechercher la panne d’un appareil simple puis intervenir concrètement pour le remettre en service. | G7: MOYENNE | H7: A_SURVEILLER | I7: FORTE | J7: MAINTIEN_REECRIT | K7: Rechercher la panne d’un appareil simple puis intervenir concrètement pour le remettre en service. | L7: Retenu pour couverture de facette et formulation rendue directement concrète. | M7: PIP-BANK-0.4
A8: PIP-SIT-R-R2-007 | B8: R | C8: R2 | D8: SIT | E8: Intervenir lorsqu’un équipement doit être réglé ou remis en service. | F8: Un équipement fonctionne mal : le régler, remplacer l’élément défectueux et tester le résultat. | G8: FAIBLE_A_MOYENNE | H8: A_SURVEILLER | I8: FORTE | J8: RETRAIT_BANQUE72 | L8: Historique conservé ; item non nécessaire pour atteindre 12/dimension et ≥2/facette. | M8: PIP-BANK-0.3
A9: PIP-ENV-R-R2-008 | B9: R | C9: R2 | D9: ENV | E9: Évoluer dans un contexte où une part importante du travail consiste à entretenir et remettre en fonctionnement des équipements. | F9: Travailler dans un service où l’on entretient régulièrement des équipements et où l’on intervient en cas de panne. | G9: FAIBLE_A_MOYENNE | H9: FAIBLE | I9: MOYENNE | J9: RETRAIT_BANQUE72 | L9: Historique conservé ; item non nécessaire pour atteindre 12/dimension et ≥2/facette. | M9: PIP-BANK-0.3
A10: PIP-ACT-R-R3-009 | B10: R | C10: R3 | D10: ACT | E10: Utiliser des outils pour réaliser une tâche concrète avec précision. | F10: Utiliser des outils de mesure et des outils manuels pour réaliser un montage avec précision. | G10: MOYENNE | H10: FAIBLE | I10: FORTE | J10: MAINTIEN_REECRIT | K10: Utiliser des outils de mesure et des outils manuels pour réaliser un montage avec précision. | L10: Retenu pour couverture de facette et formulation rendue directement concrète. | M10: PIP-BANK-0.4
A11: PIP-ACT-R-R3-010 | B11: R | C11: R3 | D11: ACT | E11: Piloter ou régler une machine pour obtenir le résultat attendu. | F11: Régler une machine ou un équipement pour obtenir une dimension, une forme ou un résultat précis. | G11: MOYENNE | H11: FAIBLE | I11: FORTE | J11: MAINTIEN_REECRIT | K11: Régler une machine ou un équipement pour obtenir une dimension, une forme ou un résultat précis. | L11: Retenu pour couverture de facette et formulation rendue directement concrète. | M11: PIP-BANK-0.4
A12: PIP-SIT-R-R3-011 | B12: R | C12: R3 | D12: SIT | E12: Prendre en charge une tâche qui nécessite de manipuler directement un appareil ou un équipement. | F12: Réaliser une opération qui demande de manipuler directement un appareil, une machine ou un instrument. | G12: FAIBLE_A_MOYENNE | H12: FAIBLE | I12: FORTE | J12: MAINTIEN_REECRIT | K12: Réaliser une opération qui demande de manipuler directement un appareil, une machine ou un instrument. | L12: Retenu pour couverture de facette et formulation rendue directement concrète. | M12: PIP-BANK-0.4
A13: PIP-ENV-R-R3-012 | B13: R | C13: R3 | D13: ENV | E13: Travailler dans un environnement où l’on utilise régulièrement des outils, des instruments ou des machines pour agir sur le réel. | F13: Travailler dans un environnement où l’usage d’outils, d’instruments ou de machines fait partie du quotidien. | G13: FAIBLE_A_MOYENNE | H13: FAIBLE | I13: MOYENNE | J13: RETRAIT_BANQUE72 | L13: Historique conservé ; item non nécessaire pour atteindre 12/dimension et ≥2/facette. | M13: PIP-BANK-0.3
A14: PIP-ACT-R-R4-013 | B14: R | C14: R4 | D14: ACT | E14: Se rendre sur différents sites pour intervenir directement sur le terrain. | F14: Se déplacer sur plusieurs sites pour constater une situation et intervenir directement sur place. | G14: MOYENNE | H14: FAIBLE | I14: FORTE | J14: MAINTIEN_REECRIT | K14: Se déplacer sur plusieurs sites pour constater une situation et intervenir directement sur place. | L14: Retenu pour couverture de facette et formulation rendue directement concrète. | M14: PIP-BANK-0.4
A15: PIP-ACT-R-R4-014 | B15: R | C15: R4 | D15: ACT | E15: Réaliser une activité professionnelle principalement en extérieur. | F15: Passer l’essentiel de sa journée de travail dehors, sur un chantier, un site naturel ou un espace extérieur. | G15: MOYENNE | H15: FAIBLE | I15: FORTE | J15: MAINTIEN_REECRIT | K15: Passer l’essentiel de sa journée de travail dehors, sur un chantier, un site naturel ou un espace extérieur. | L15: Retenu pour couverture de facette et formulation rendue directement concrète. | M15: PIP-BANK-0.4
A16: PIP-SIT-R-R4-015 | B16: R | C16: R4 | D16: SIT | E16: Intervenir sur place lorsqu’une situation concrète doit être traitée directement plutôt qu’à distance. | F16: Un problème apparaît sur un site : aller sur place pour observer la situation et agir immédiatement. | G16: FAIBLE_A_MOYENNE | H16: FAIBLE | I16: FORTE | J16: RETRAIT_BANQUE72 | L16: Historique conservé ; item non nécessaire pour atteindre 12/dimension et ≥2/facette. | M16: PIP-BANK-0.3
A17: PIP-ENV-R-R4-016 | B17: R | C17: R4 | D17: ENV | E17: Travailler dans un contexte où l’activité se déroule souvent sur le terrain, au contact direct de l’environnement réel. | F17: Exercer un métier où l’on est souvent sur le terrain plutôt que derrière un bureau. | G17: FAIBLE_A_MOYENNE | H17: FAIBLE | I17: MOYENNE | J17: RETRAIT_BANQUE72 | L17: Historique conservé ; item non nécessaire pour atteindre 12/dimension et ≥2/facette. | M17: PIP-BANK-0.3
A18: PIP-ACT-R-R5-017 | B18: R | C18: R5 | D18: ACT | E18: S’occuper concrètement de plantes ou d’animaux dans le cadre du travail. | F18: S’occuper concrètement de cultures, de plantes ou d’animaux : nourrir, entretenir, surveiller leur état. | G18: MOYENNE | H18: A_SURVEILLER | I18: FORTE | J18: MAINTIEN_REECRIT | K18: S’occuper concrètement de cultures, de plantes ou d’animaux : nourrir, entretenir, surveiller leur état. | L18: Retenu pour couverture de facette et formulation rendue directement concrète. | M18: PIP-BANK-0.4
A19: PIP-ACT-R-R5-018 | B19: R | C19: R5 | D19: ACT | E19: Manipuler des matériaux ou des produits pour réaliser une tâche physique utile. | F19: Manipuler des matériaux, déplacer des éléments ou préparer physiquement des produits pour réaliser une opération utile. | G19: MOYENNE | H19: FAIBLE | I19: FORTE | J19: MAINTIEN_REECRIT | K19: Manipuler des matériaux, déplacer des éléments ou préparer physiquement des produits pour réaliser une opération utile. | L19: Retenu pour couverture de facette et formulation rendue directement concrète. | M19: PIP-BANK-0.4
A20: PIP-SIT-R-R5-019 | B20: R | C20: R5 | D20: SIT | E20: Prendre en charge une activité où il faut agir directement sur du vivant, de la matière ou un environnement physique. | F20: Prendre en charge une tâche nécessitant d’agir directement sur des matières, des plantes, des animaux ou un espace physique. | G20: FAIBLE_A_MOYENNE | H20: FAIBLE | I20: FORTE | J20: RETRAIT_BANQUE72 | L20: Historique conservé ; item non nécessaire pour atteindre 12/dimension et ≥2/facette. | M20: PIP-BANK-0.3
A21: PIP-ENV-R-R5-020 | B21: R | C21: R5 | D21: ENV | E21: Évoluer dans un environnement où le travail implique régulièrement une action physique concrète sur des matières, des plantes, des animaux ou des objets. | F21: Travailler dans un environnement où l’activité implique régulièrement de manipuler des matières, des objets ou du vivant. | G21: FAIBLE_A_MOYENNE | H21: FAIBLE | I21: MOYENNE | J21: RETRAIT_BANQUE72 | L21: Historique conservé ; item non nécessaire pour atteindre 12/dimension et ≥2/facette. | M21: PIP-BANK-0.3
A22: PIP-ACT-I-I1-001 | B22: I | C22: I1 | D22: ACT | E22: Observer attentivement une situation pour en repérer les caractéristiques importantes. | F22: Observer un fonctionnement, un phénomène ou une situation et relever les détails importants avant de conclure. | G22: MOYENNE | H22: FAIBLE | I22: FORTE | J22: MAINTIEN_REECRIT | K22: Observer un fonctionnement, un phénomène ou une situation et relever les détails importants avant de conclure. | L22: Retenu pour couverture de facette et formulation rendue directement concrète. | M22: PIP-BANK-0.4
A23: PIP-ACT-I-I1-002 | B23: I | C23: I1 | D23: ACT | E23: Comparer plusieurs informations ou observations pour identifier ce qui les distingue. | F23: Comparer deux séries d’informations ou d’observations pour identifier précisément ce qui diffère. | G23: MOYENNE | H23: FAIBLE | I23: FORTE | J23: MAINTIEN_REECRIT | K23: Comparer deux séries d’informations ou d’observations pour identifier précisément ce qui diffère. | L23: Retenu pour couverture de facette et formulation rendue directement concrète. | M23: PIP-BANK-0.4
A24: PIP-SIT-I-I1-003 | B24: I | C24: I1 | D24: SIT | E24: Examiner une situation nouvelle afin de comprendre précisément ce qui s’y passe. | F24: Face à une situation inhabituelle, prendre le temps d’examiner les faits avant d’avancer une explication. | G24: FAIBLE_A_MOYENNE | H24: FAIBLE | I24: FORTE | J24: MAINTIEN_REECRIT | K24: Face à une situation inhabituelle, prendre le temps d’examiner les faits avant d’avancer une explication. | L24: Retenu pour couverture de facette et formulation rendue directement concrète. | M24: PIP-BANK-0.4
A25: PIP-ENV-I-I1-004 | B25: I | C25: I1 | D25: ENV | E25: Travailler dans un contexte où l’on dispose de temps pour observer et examiner les faits avant de tirer des conclusions. | F25: Travailler dans un contexte où l’on peut observer, vérifier et examiner les faits avant de prendre position. | G25: FAIBLE_A_MOYENNE | H25: FAIBLE | I25: MOYENNE | J25: RETRAIT_BANQUE72 | L25: Historique conservé ; item non nécessaire pour atteindre 12/dimension et ≥2/facette. | M25: PIP-BANK-0.3
A26: PIP-ACT-I-I2-005 | B26: I | C26: I2 | D26: ACT | E26: Analyser plusieurs informations pour comprendre les liens entre elles. | F26: Analyser plusieurs données pour comprendre comment elles sont liées et ce qu’elles expliquent. | G26: MOYENNE | H26: FAIBLE | I26: FORTE | J26: MAINTIEN_REECRIT | K26: Analyser plusieurs données pour comprendre comment elles sont liées et ce qu’elles expliquent. | L26: Retenu pour couverture de facette et formulation rendue directement concrète. | M26: PIP-BANK-0.4
A27: PIP-ACT-I-I2-006 | B27: I | C27: I2 | D27: ACT | E27: Décomposer un problème complexe en plusieurs éléments pour mieux le comprendre. | F27: Découper un problème complexe en plusieurs questions plus simples afin d’en comprendre la logique. | G27: MOYENNE | H27: FAIBLE | I27: FORTE | J27: MAINTIEN_REECRIT | K27: Découper un problème complexe en plusieurs questions plus simples afin d’en comprendre la logique. | L27: Retenu pour couverture de facette et formulation rendue directement concrète. | M27: PIP-BANK-0.4
A28: PIP-SIT-I-I2-007 | B28: I | C28: I2 | D28: SIT | E28: Faire face à un problème où il faut raisonner étape par étape avant de trouver une explication. | F28: Un problème n’a pas de réponse évidente : raisonner étape par étape pour comprendre ce qui se passe. | G28: FAIBLE_A_MOYENNE | H28: FAIBLE | I28: FORTE | J28: MAINTIEN_REECRIT | K28: Un problème n’a pas de réponse évidente : raisonner étape par étape pour comprendre ce qui se passe. | L28: Retenu pour couverture de facette et formulation rendue directement concrète. | M28: PIP-BANK-0.4
A29: PIP-ENV-I-I2-008 | B29: I | C29: I2 | D29: ENV | E29: Évoluer dans un contexte où l’on doit régulièrement interpréter des informations et construire un raisonnement. | F29: Exercer dans un environnement où l’on doit souvent interpréter des informations et construire un raisonnement argumenté. | G29: FAIBLE_A_MOYENNE | H29: FAIBLE | I29: MOYENNE | J29: RETRAIT_BANQUE72 | L29: Historique conservé ; item non nécessaire pour atteindre 12/dimension et ≥2/facette. | M29: PIP-BANK-0.3
A30: PIP-ACT-I-I3-009 | B30: I | C30: I3 | D30: ACT | E30: Rechercher des informations provenant de plusieurs sources pour répondre à une question. | F30: Chercher des informations dans plusieurs sources fiables pour répondre à une question précise. | G30: MOYENNE | H30: FAIBLE | I30: FORTE | J30: MAINTIEN_REECRIT | K30: Chercher des informations dans plusieurs sources fiables pour répondre à une question précise. | L30: Retenu pour couverture de facette et formulation rendue directement concrète. | M30: PIP-BANK-0.4
A31: PIP-ACT-I-I3-010 | B31: I | C31: I3 | D31: ACT | E31: Enquêter pour vérifier ce qui est exact lorsqu’une situation reste incertaine. | F31: Vérifier une information incertaine en recoupant des sources et en recherchant des éléments de preuve. | G31: MOYENNE | H31: FAIBLE | I31: FORTE | J31: MAINTIEN_REECRIT | K31: Vérifier une information incertaine en recoupant des sources et en recherchant des éléments de preuve. | L31: Retenu pour couverture de facette et formulation rendue directement concrète. | M31: PIP-BANK-0.4
A32: PIP-SIT-I-I3-011 | B32: I | C32: I3 | D32: SIT | E32: Être confronté à une question sans réponse immédiate et devoir approfondir les recherches pour la comprendre. | F32: Une question reste sans réponse : approfondir la recherche jusqu’à comprendre les éléments essentiels. | G32: FAIBLE_A_MOYENNE | H32: FAIBLE | I32: FORTE | J32: RETRAIT_BANQUE72 | L32: Historique conservé ; item non nécessaire pour atteindre 12/dimension et ≥2/facette. | M32: PIP-BANK-0.3
A33: PIP-ENV-I-I3-012 | B33: I | C33: I3 | D33: ENV | E33: Travailler dans un contexte où l’on peut explorer des sujets, consulter des sources et approfondir des questions. | F33: Travailler dans un contexte où l’on dispose régulièrement de temps pour chercher, documenter et approfondir des sujets. | G33: FAIBLE_A_MOYENNE | H33: FAIBLE | I33: MOYENNE | J33: RETRAIT_BANQUE72 | L33: Historique conservé ; item non nécessaire pour atteindre 12/dimension et ≥2/facette. | M33: PIP-BANK-0.3
A34: PIP-ACT-I-I4-013 | B34: I | C34: I4 | D34: ACT | E34: Tester une hypothèse pour voir si elle se vérifie. | F34: Tester une hypothèse en définissant une manière simple de vérifier si elle se confirme. | G34: MOYENNE | H34: FAIBLE | I34: FORTE | J34: MAINTIEN_REECRIT | K34: Tester une hypothèse en définissant une manière simple de vérifier si elle se confirme. | L34: Retenu pour couverture de facette et formulation rendue directement concrète. | M34: PIP-BANK-0.4
A35: PIP-ACT-I-I4-014 | B35: I | C35: I4 | D35: ACT | E35: Comparer plusieurs essais pour comprendre ce qui produit un résultat différent. | F35: Réaliser plusieurs essais en modifiant un paramètre pour comprendre ce qui change le résultat. | G35: MOYENNE | H35: FAIBLE | I35: FORTE | J35: MAINTIEN_REECRIT | K35: Réaliser plusieurs essais en modifiant un paramètre pour comprendre ce qui change le résultat. | L35: Retenu pour couverture de facette et formulation rendue directement concrète. | M35: PIP-BANK-0.4
A36: PIP-SIT-I-I4-015 | B36: I | C36: I4 | D36: SIT | E36: Chercher la meilleure explication d’un phénomène en réalisant des essais ou des mesures. | F36: Pour expliquer un phénomène, effectuer des mesures ou des essais et comparer les résultats obtenus. | G36: FAIBLE_A_MOYENNE | H36: FAIBLE | I36: FORTE | J36: RETRAIT_BANQUE72 | L36: Historique conservé ; item non nécessaire pour atteindre 12/dimension et ≥2/facette. | M36: PIP-BANK-0.3
A37: PIP-ENV-I-I4-016 | B37: I | C37: I4 | D37: ENV | E37: Évoluer dans un contexte où l’on peut expérimenter, mesurer et tirer des enseignements des résultats. | F37: Évoluer dans un environnement où l’on peut tester, mesurer, expérimenter et apprendre des résultats. | G37: FAIBLE_A_MOYENNE | H37: FAIBLE | I37: MOYENNE | J37: RETRAIT_BANQUE72 | L37: Historique conservé ; item non nécessaire pour atteindre 12/dimension et ≥2/facette. | M37: PIP-BANK-0.3
A38: PIP-ACT-I-I5-017 | B38: I | C38: I5 | D38: ACT | E38: Chercher la cause d’un problème pour pouvoir l’expliquer. | F38: Rechercher la cause d’un dysfonctionnement ou d’un phénomène avant de proposer une explication. | G38: MOYENNE | H38: FAIBLE | I38: FORTE | J38: MAINTIEN_REECRIT | K38: Rechercher la cause d’un dysfonctionnement ou d’un phénomène avant de proposer une explication. | L38: Retenu pour couverture de facette et formulation rendue directement concrète. | M38: PIP-BANK-0.4
A39: PIP-ACT-I-I5-018 | B39: I | C39: I5 | D39: ACT | E39: Résoudre un problème nouveau en construisant une solution fondée sur les informations disponibles. | F39: Résoudre un problème nouveau en utilisant les informations disponibles pour construire une solution raisonnée. | G39: MOYENNE | H39: FAIBLE | I39: FORTE | J39: MAINTIEN_REECRIT | K39: Résoudre un problème nouveau en utilisant les informations disponibles pour construire une solution raisonnée. | L39: Retenu pour couverture de facette et formulation rendue directement concrète. | M39: PIP-BANK-0.4
A40: PIP-SIT-I-I5-019 | B40: I | C40: I5 | D40: SIT | E40: Prendre en charge une situation complexe dont la solution n’est pas connue à l’avance et qui demande d’abord de comprendre le problème. | F40: Face à une situation complexe et inédite, comprendre d’abord le problème avant d’élaborer une solution. | G40: FAIBLE_A_MOYENNE | H40: A_SURVEILLER | I40: FORTE | J40: RETRAIT_BANQUE72 | L40: Historique conservé ; item non nécessaire pour atteindre 12/dimension et ≥2/facette. | M40: PIP-BANK-0.3
...

Sheet DIMENSIONS
A1: DIMENSIONS & FACETTES RIASEC
A2: 6 dimensions / 30 facettes — référentiel V1.0
A4: facette_id | B4: dimension | C4: dimension_nom | D4: facette_nom | E4: definition_dimension | F4: noyau_dimension | G4: ce_que_le_score_ne_mesure_pas | H4: description_facette | I4: verbes_indicatifs | J4: statut
A5: R1 | B5: R | C5: Réaliste | D5: Construire / fabriquer / transformer | E5: Attirance pour des activités où l’on agit concrètement sur le monde physique : construire, fabriquer, installer, réparer, utiliser des outils ou équipements, intervenir sur des matières, objets, systèmes, organismes ou environnements réels, et résoudre des problèmes pratiques par l’action. | F5: Action concrète sur le réel et résultat tangible. | G5: Ni dextérité, ni niveau technique, ni goût exclusif pour le travail manuel. | H5: Création ou transformation concrète d’objets, structures ou matières. | I5: Assembler, fabriquer, construire, façonner, transformer | J5: ACTIF
A6: R2 | B6: R | C6: Réaliste | D6: Installer / réparer / maintenir | E6: Attirance pour des activités où l’on agit concrètement sur le monde physique : construire, fabriquer, installer, réparer, utiliser des outils ou équipements, intervenir sur des matières, objets, systèmes, organismes ou environnements réels, et résoudre des problèmes pratiques par l’action. | F6: Action concrète sur le réel et résultat tangible. | G6: Ni dextérité, ni niveau technique, ni goût exclusif pour le travail manuel. | H6: Diagnostic pratique suivi d’une intervention concrète visant le fonctionnement. | I6: Installer, régler, réparer, entretenir, remettre en service | J6: ACTIF
A7: R3 | B7: R | C7: Réaliste | D7: Outils / machines / équipements | E7: Attirance pour des activités où l’on agit concrètement sur le monde physique : construire, fabriquer, installer, réparer, utiliser des outils ou équipements, intervenir sur des matières, objets, systèmes, organismes ou environnements réels, et résoudre des problèmes pratiques par l’action. | F7: Action concrète sur le réel et résultat tangible. | G7: Ni dextérité, ni niveau technique, ni goût exclusif pour le travail manuel. | H7: Usage direct d’outils, machines, instruments ou équipements techniques. | I7: Manipuler, piloter, régler, utiliser un équipement | J7: ACTIF
A8: R4 | B8: R | C8: Réaliste | D8: Terrain / environnement concret | E8: Attirance pour des activités où l’on agit concrètement sur le monde physique : construire, fabriquer, installer, réparer, utiliser des outils ou équipements, intervenir sur des matières, objets, systèmes, organismes ou environnements réels, et résoudre des problèmes pratiques par l’action. | F8: Action concrète sur le réel et résultat tangible. | G8: Ni dextérité, ni niveau technique, ni goût exclusif pour le travail manuel. | H8: Action dans des contextes physiques, extérieurs ou directement liés à un environnement réel. | I8: Intervenir sur site, travailler dehors, se déplacer sur le terrain | J8: ACTIF
A9: R5 | B9: R | C9: Réaliste | D9: Vivant / matière / action physique | E9: Attirance pour des activités où l’on agit concrètement sur le monde physique : construire, fabriquer, installer, réparer, utiliser des outils ou équipements, intervenir sur des matières, objets, systèmes, organismes ou environnements réels, et résoudre des problèmes pratiques par l’action. | F9: Action concrète sur le réel et résultat tangible. | G9: Ni dextérité, ni niveau technique, ni goût exclusif pour le travail manuel. | H9: Activités pratiques impliquant plantes, animaux, matière, effort corporel ou intervention physique finalisée. | I9: S’occuper d’animaux ou cultures, manipuler des matériaux | J9: ACTIF
A10: I1 | B10: I | C10: Investigateur | D10: Observer / examiner | E10: Attirance pour des activités où l’on cherche à comprendre, examiner, expliquer ou résoudre des questions en mobilisant observation, analyse, raisonnement, recherche d’informations, expérimentation ou mise en relation d’idées et de faits. | F10: Comprendre, rechercher, expliquer et résoudre. | G10: Ni intelligence, ni niveau scolaire, ni étiquette de scientifique. | H10: Examen attentif de faits, phénomènes, informations ou situations. | I10: Observer, examiner, comparer, repérer, documenter | J10: ACTIF
A11: I2 | B11: I | C11: Investigateur | D11: Analyser / raisonner | E11: Attirance pour des activités où l’on cherche à comprendre, examiner, expliquer ou résoudre des questions en mobilisant observation, analyse, raisonnement, recherche d’informations, expérimentation ou mise en relation d’idées et de faits. | F11: Comprendre, rechercher, expliquer et résoudre. | G11: Ni intelligence, ni niveau scolaire, ni étiquette de scientifique. | H11: Décomposition d’un problème et mise en relation d’informations. | I11: Analyser, relier, déduire, interpréter, modéliser | J11: ACTIF
A12: I3 | B12: I | C12: Investigateur | D12: Rechercher / enquêter | E12: Attirance pour des activités où l’on cherche à comprendre, examiner, expliquer ou résoudre des questions en mobilisant observation, analyse, raisonnement, recherche d’informations, expérimentation ou mise en relation d’idées et de faits. | F12: Comprendre, rechercher, expliquer et résoudre. | G12: Ni intelligence, ni niveau scolaire, ni étiquette de scientifique. | H12: Recherche d’informations, preuves ou explications lorsqu’une question reste ouverte. | I12: Rechercher, enquêter, vérifier, approfondir, confronter des sources | J12: ACTIF
A13: I4 | B13: I | C13: Investigateur | D13: Expérimenter / tester | E13: Attirance pour des activités où l’on cherche à comprendre, examiner, expliquer ou résoudre des questions en mobilisant observation, analyse, raisonnement, recherche d’informations, expérimentation ou mise en relation d’idées et de faits. | F13: Comprendre, rechercher, expliquer et résoudre. | G13: Ni intelligence, ni niveau scolaire, ni étiquette de scientifique. | H13: Mise à l’épreuve d’hypothèses ou solutions afin d’apprendre du résultat. | I13: Tester, expérimenter, mesurer, essayer | J13: ACTIF
A14: I5 | B14: I | C14: Investigateur | D14: Résoudre / expliquer | E14: Attirance pour des activités où l’on cherche à comprendre, examiner, expliquer ou résoudre des questions en mobilisant observation, analyse, raisonnement, recherche d’informations, expérimentation ou mise en relation d’idées et de faits. | F14: Comprendre, rechercher, expliquer et résoudre. | G14: Ni intelligence, ni niveau scolaire, ni étiquette de scientifique. | H14: Problèmes intellectuels dont l’enjeu est de comprendre, expliquer ou trouver une solution fondée. | I14: Résoudre, expliquer, diagnostiquer intellectuellement, conceptualiser | J14: ACTIF
A15: A1 | B15: A | C15: Artistique | D15: Imaginer / inventer | E15: Attirance pour des activités où l’on imagine, crée, compose, conçoit ou exprime quelque chose avec un espace d’originalité, d’interprétation, de sensibilité ou de choix personnel. | F15: Créer, concevoir ou exprimer avec ouverture. | G15: Ni talent artistique, ni originalité personnelle mesurée, ni obligation de métier culturel. | H15: Génération d’idées, concepts, scénarios ou formes nouvelles. | I15: Imaginer, inventer, proposer, explorer, détourner | J15: ACTIF
... A34: C5 | B34: C | C34: Conventionnel | D34: Traiter / suivre dossiers, données et opérations | E34: Attirance pour des activités où l’on organise, enregistre, classe, traite, vérifie ou suit des informations, données, dossiers, transactions ou ressources dans un cadre structuré. | F34: Structurer, fiabiliser et suivre méthodiquement. | G34: Ni rigidité, ni conscienciosité, ni routine, ni compétence administrative. | H34: Faire avancer méthodiquement dossiers, données, opérations ou transactions en assurant leur suivi. | I34: Traiter, suivre, planifier des échéances, rapprocher, clôturer | J34: ACTIF

Sheet QUESTIONS
A1: BANQUE EXPÉRIMENTALE PIP — QUESTIONS
A2: 120 items historiques conservés. V0.5 : décision documentée de passage à 72 items ; les formulations V0.4 restent intactes dans cette feuille.
A4: item_id | B4: item_version | C4: statut | D4: date_creation | E4: date_modification | F4: bloc | G4: famille_formulation | H4: dimension | I4: facette | J4: dimensions_concurrentes | K4: texte_fr | L4: reponse_1 | M4: reponse_2 | N4: reponse_3 | O4: reponse_4 | P4: reponse_5 | Q4: score_1 | R4: score_2 | S4: score_3 | T4: score_4 | U4: score_5 | V4: justification_dimension | W4: justification_facette | X4: commentaire_concepteur | Y4: risque_genre | Z4: risque_age_generation | AA4: risque_origine_culturelle_sociale | AB4: risque_niveau_etudes | AC4: risque_langue_litteratie | AD4: risque_accessibilite | AE4: risque_familiarite_numerique | AF4: risque_prestige | AG4: risque_familiarite_sectorielle | AH4: risque_desirabilite | AI4: risque_hybridite | AJ4: n_passations | AK4: indicateurs_item | AL4: decision_validation | AM4: motif_retrait | AN4: version_questionnaire_entree | AO4: version_questionnaire_sortie | AP4: controle_ligne
A5: PIP-ACT-R-R1-001 | B5: 0.2 | C5: PILOTE | D5: 08/09/2026 | E5: 08/09/2026 | F5: ACT | G5: Verbe d’action + objet/contexte | H5: R | I5: R1 | J5: A | K5: Assembler des éléments pour fabriquer un objet fonctionnel. | L5: Cela ne m’attire pas du tout | M5: Cela m’attire peu | N5: Je suis partagé(e) / sans préférence marquée | O5: Cela m’attire | P5: Cela m’attire beaucoup | Q5: 1 | R5: 2 | S5: 3 | T5: 4 | U5: 5 | V5: La formulation cible l’intérêt pour action concrète sur le réel et résultat tangible. Elle mobilise un comportement caractéristique de la dimension R (Réaliste) sans demander un niveau de compétence préalable. | W5: L’item relève de R1 — Construire / fabriquer / transformer : Création ou transformation concrète d’objets, structures ou matières. | X5: Revue méthodologique V0.3 : surveiller projection en cas de limitation physique ou sensorielle, familiarité avec le contexte professionnel au pilote. | Y5: FAIBLE | Z5: FAIBLE | AA5: FAIBLE | AB5: FAIBLE | AC5: FAIBLE | AD5: MOYEN | AE5: FAIBLE | AF5: FAIBLE | AG5: MOYEN | AH5: FAIBLE | AI5: FAIBLE | AJ5: 0 | AL5: RETENU_V0.5_REECRIT_CONCRET | AN5: PIP-BANK-0.3 | AO5: PIP-BANK-0.4 | AP5: =IF(OR(C5="PILOTE",C5="ACTIF"),IF(AND(A5<>"",H5<>"",I5<>"",K5<>"",V5<>"",W5<>""),"OK","A_COMPLETER"),"OK_STRUCTURE")
A6: PIP-ACT-R-R1-002 | B6: 0.2 | C6: PILOTE | D6: 08/09/2026 | E6: 08/09/2026 | F6: ACT | G6: Verbe d’action + objet/contexte | H6: R | I6: R1 | J6: A | K6: Transformer une matière ou un matériau pour lui donner une forme utile. | L6: Cela ne m’attire pas du tout | M6: Cela m’attire peu | N6: Je suis partagé(e) / sans préférence marquée | O6: Cela m’attire | P6: Cela m’attire beaucoup | Q6: 1 | R6: 2 | S6: 3 | T6: 4 | U6: 5 | V6: La formulation cible l’intérêt pour action concrète sur le réel et résultat tangible. Elle mobilise un comportement caractéristique de la dimension R (Réaliste) sans demander un niveau de compétence préalable. | W6: L’item relève de R1 — Construire / fabriquer / transformer : Création ou transformation concrète d’objets, structures ou matières. | X6: Revue méthodologique V0.3 : surveiller projection en cas de limitation physique ou sensorielle, familiarité avec le contexte professionnel au pilote. | Y6: FAIBLE | Z6: FAIBLE | AA6: FAIBLE | AB6: FAIBLE | AC6: FAIBLE | AD6: MOYEN | AE6: FAIBLE | AF6: FAIBLE | AG6: MOYEN | AH6: FAIBLE | AI6: FAIBLE | AJ6: 0 | AL6: RETENU_V0.5_REECRIT_CONCRET | AN6: PIP-BANK-0.3 | AO6: PIP-BANK-0.4 | AP6: =IF(OR(C6="PILOTE",C6="ACTIF"),IF(AND(A6<>"",H6<>"",I6<>"",K6<>"",V6<>"",W6<>""),"OK","A_COMPLETER"),"OK_STRUCTURE")
A7: PIP-SIT-R-R1-003 | B7: 0.2 | C7: PILOTE | D7: 08/09/2026 | E7: 08/09/2026 | F7: SIT | G7: Situation courte avec enjeu central | H7: R | I7: R1 | J7: A | K7: Prendre en charge la réalisation concrète d’un objet ou d’une structure à partir d’éléments séparés. | L7: Cela ne m’attire pas du tout | M7: Cela m’attire peu | N7: Je suis partagé(e) / sans préférence marquée | O7: Cela m’attire | P7: Cela m’attire beaucoup | Q7: 1 | R7: 2 | S7: 3 | T7: 4 | U7: 5 | V7: La formulation cible l’intérêt pour action concrète sur le réel et résultat tangible. Elle mobilise un comportement caractéristique de la dimension R (Réaliste) sans demander un niveau de compétence préalable. | W7: L’item relève de R1 — Construire / fabriquer / transformer : Création ou transformation concrète d’objets, structures ou matières. | X7: Revue méthodologique V0.3 : surveiller projection en cas de limitation physique ou sensorielle, familiarité avec le contexte professionnel au pilote. | Y7: FAIBLE | Z7: FAIBLE | AA7: FAIBLE | AB7: FAIBLE | AC7: FAIBLE | AD7: MOYEN | AE7: FAIBLE | AF7: FAIBLE | AG7: MOYEN | AH7: FAIBLE | AI7: FAIBLE | AJ7: 0 | AL7: RETENU_V0.5_REECRIT_CONCRET | AN7: PIP-BANK-0.3 | AO7: PIP-BANK-0.4 | AP7: =IF(OR(C7="PILOTE",C7="ACTIF"),IF(AND(A7<>"",H7<>"",I7<>"",K7<>"",V7<>"",W7<>""),"OK","A_COMPLETER"),"OK_STRUCTURE")
A8: PIP-ENV-R-R1-004 | B8: 0.2 | C8: PILOTE | D8: 08/09/2026 | E8: 08/09/2026 | F8: ENV | G8: Contexte décrit par ce qu’il permet de faire | H8: R | I8: R1 | J8: A | K8: Travailler dans un contexte où l’on voit directement le résultat matériel de ce que l’on fabrique ou transforme. | L8: Cela ne m’attire pas du tout | M8: Cela m’attire peu | N8: Je suis partagé(e) / sans préférence marquée | O8: Cela m’attire | P8: Cela m’attire beaucoup | Q8: 1 | R8: 2 | S8: 3 | T8: 4 | U8: 5 | V8: La formulation cible l’intérêt pour action concrète sur le réel et résultat tangible. Elle mobilise un comportement caractéristique de la dimension R (Réaliste) sans demander un niveau de compétence préalable. | W8: L’item relève de R1 — Construire / fabriquer / transformer : Création ou transformation concrète d’objets, structures ou matières. | X8: Revue méthodologique V0.3 : surveiller projection en cas de limitation physique ou sensorielle, familiarité avec le contexte professionnel au pilote. | Y8: FAIBLE | Z8: FAIBLE | AA8: FAIBLE | AB8: FAIBLE | AC8: FAIBLE | AD8: MOYEN | AE8: FAIBLE | AF8: FAIBLE | AG8: MOYEN | AH8: FAIBLE | AI8: FAIBLE | AJ8: 0 | AL8: RETIRE_BANQUE72_HISTORIQUE_CONSERVE | AM8: Réduction méthodologique 120→72 : doublon de facette / priorité aux activités professionnelles observables et aux items à plus faible risque. | AN8: PIP-BANK-0.3 | AO8: PIP-BANK-0.3 | AP8: =IF(OR(C8="PILOTE",C8="ACTIF"),IF(AND(A8<>"",H8<>"",I8<>"",K8<>"",V8<>"",W8<>""),"OK","A_COMPLETER"),"OK_STRUCTURE")
A9: PIP-ACT-R-R2-005 | B9: 0.2 | C9: PILOTE | D9: 08/09/2026 | E9: 08/09/2026 | F9: ACT | G9: Verbe d’action + objet/contexte | H9: R | I9: R2 | J9: I | K9: Installer un équipement pour qu’il soit prêt à fonctionner. | L9: Cela ne m’attire pas du tout | M9: Cela m’attire peu | N9: Je suis partagé(e) / sans préférence marquée | O9: Cela m’attire | P9: Cela m’attire beaucoup | Q9: 1 | R9: 2 | S9: 3 | T9: 4 | U9: 5 | V9: La formulation cible l’intérêt pour action concrète sur le réel et résultat tangible. Elle mobilise un comportement caractéristique de la dimension R (Réaliste) sans demander un niveau de compétence préalable. | W9: L’item relève de R2 — Installer / réparer / maintenir : Diagnostic pratique suivi d’une intervention concrète visant le fonctionnement. | X9: Revue méthodologique V0.3 : surveiller projection en cas de limitation physique ou sensorielle, familiarité avec le contexte professionnel au pilote. | Y9: FAIBLE | Z9: FAIBLE | AA9: FAIBLE | AB9: FAIBLE | AC9: FAIBLE | AD9: MOYEN | AE9: FAIBLE | AF9: FAIBLE | AG9: MOYEN | AH9: FAIBLE | AI9: FAIBLE | AJ9: 0 | AL9: RETENU_V0.5_REECRIT_CONCRET | AN9: PIP-BANK-0.3 | AO9: PIP-BANK-0.4 | AP9: =IF(OR(C9="PILOTE",C9="ACTIF"),IF(AND(A9<>"",H9<>"",I9<>"",K9<>"",V9<>"",W9<>""),"OK","A_COMPLETER"),"OK_STRUCTURE")
A10: PIP-ACT-R-R2-006 | B10: 0.2 | C10: PILOTE | D10: 08/09/2026 | E10: 08/09/2026 | F10: ACT | G10: Verbe d’action + objet/contexte | H10: R | I10: R2 | J10: I | K10: Réparer un matériel qui ne fonctionne plus correctement. | L10: Cela ne m’attire pas du tout | M10: Cela m’attire peu | N10: Je suis partagé(e) / sans préférence marquée | O10: Cela m’attire | P10: Cela m’attire beaucoup | Q10: 1 | R10: 2 | S10: 3 | T10: 4 | U10: 5 | V10: La formulation cible l’intérêt pour action concrète sur le réel et résultat tangible. Elle mobilise un comportement caractéristique de la dimension R (Réaliste) sans demander un niveau de compétence préalable. | W10: L’item relève de R2 — Installer / réparer / maintenir : Diagnostic pratique suivi d’une intervention concrète visant le fonctionnement. | X10: Revue méthodologique V0.3 : surveiller projection en cas de limitation physique ou sensorielle, familiarité avec le contexte professionnel, frontière avec I au pilote. | Y10: FAIBLE | Z10: FAIBLE | AA10: FAIBLE | AB10: FAIBLE | AC10: FAIBLE | AD10: MOYEN | AE10: FAIBLE | AF10: FAIBLE | AG10: MOYEN | AH10: FAIBLE | AI10: MOYEN | AJ10: 0 | AL10: RETENU_V0.5_REECRIT_CONCRET | AN10: PIP-BANK-0.3 | AO10: PIP-BANK-0.4 | AP10: =IF(OR(C10="PILOTE",C10="ACTIF"),IF(AND(A10<>"",H10<>"",I10<>"",K10<>"",V10<>"",W10<>""),"OK","A_COMPLETER"),"OK_STRUCTURE")
A11: PIP-SIT-R-R2-007 | B11: 0.2 | C11: PILOTE | D11: 08/09/2026 | E11: 08/09/2026 | F11: SIT | G11: Situation courte avec enjeu central | H11: R | I11: R2 | J11: I | K11: Intervenir lorsqu’un équipement doit être réglé ou remis en service. | L11: Cela ne m’attire pas du tout | M11: Cela m’attire peu | N11: Je suis partagé(e) / sans préférence marquée | O11: Cela m’attire | P11: Cela m’attire beaucoup | Q11: 1 | R11: 2 | S11: 3 | T11: 4 | U11: 5 | V11: La formulation cible l’intérêt pour action concrète sur le réel et résultat tangible. Elle mobilise un comportement caractéristique de la dimension R (Réaliste) sans demander un niveau de compétence préalable. | W11: L’item relève de R2 — Installer / réparer / maintenir : Diagnostic pratique suivi d’une intervention concrète visant le fonctionnement. | X11: Revue méthodologique V0.3 : surveiller projection en cas de limitation physique ou sensorielle, familiarité avec le contexte professionnel, frontière avec I au pilote. | Y11: FAIBLE | Z11: FAIBLE | AA11: FAIBLE | AB11: FAIBLE | AC11: FAIBLE | AD11: MOYEN | AE11: FAIBLE | AF11: FAIBLE | AG11: MOYEN | AH11: FAIBLE | AI11: MOYEN | AJ11: 0 | AL11: RETIRE_BANQUE72_HISTORIQUE_CONSERVE | AM11: Réduction méthodologique 120→72 : doublon de facette / priorité aux activités professionnelles observables et aux items à plus faible risque. | AN11: PIP-BANK-0.3 | AO11: PIP-BANK-0.3 | AP11: =IF(OR(C11="PILOTE",C11="ACTIF"),IF(AND(A11<>"",H11<>"",I11<>"",K11<>"",V11<>"",W11<>""),"OK","A_COMPLETER"),"OK_STRUCTURE")
A12: PIP-ENV-R-R2-008 | B12: 0.2 | C12: PILOTE | D12: 08/09/2026 | E12: 08/09/2026 | F12: ENV | G12: Contexte décrit par ce qu’il permet de faire | H12: R | I12: R2 | J12: I | K12: Évoluer dans un contexte où une part importante du travail consiste à entretenir et remettre en fonctionnement des équipements. | L12: Cela ne m’attire pas du tout | M12: Cela m’attire peu | N12: Je suis partagé(e) / sans préférence marquée | O12: Cela m’attire | P12: Cela m’attire beaucoup | Q12: 1 | R12: 2 | S12: 3 | T12: 4 | U12: 5 | V12: La formulation cible l’intérêt pour action concrète sur le réel et résultat tangible. Elle mobilise un comportement caractéristique de la dimension R (Réaliste) sans demander un niveau de compétence préalable. | W12: L’item relève de R2 — Installer / réparer / maintenir : Diagnostic pratique suivi d’une intervention concrète visant le fonctionnement. | X12: Revue méthodologique V0.3 : surveiller projection en cas de limitation physique ou sensorielle, familiarité avec le contexte professionnel au pilote. | Y12: FAIBLE | Z12: FAIBLE | AA12: FAIBLE | AB12: FAIBLE | AC12: FAIBLE | AD12: MOYEN | AE12: FAIBLE | AF12: FAIBLE | AG12: MOYEN | AH12: FAIBLE | AI12: FAIBLE | AJ12: 0 | AL12: RETIRE_BANQUE72_HISTORIQUE_CONSERVE | AM12: Réduction méthodologique 120→72 : doublon de facette / priorité aux activités professionnelles observables et aux items à plus faible risque. | AN12: PIP-BANK-0.3 | AO12: PIP-BANK-0.3 | AP12: =IF(OR(C12="PILOTE",C12="ACTIF"),IF(AND(A12<>"",H12<>"",I12<>"",K12<>"",V12<>"",W12<>""),"OK","A_COMPLETER"),"OK_STRUCTURE")
A13: PIP-ACT-R-R3-009 | B13: 0.2 | C13: PILOTE | D13: 08/09/2026 | E13: 08/09/2026 | F13: ACT | G13: Verbe d’action + objet/contexte | H13: R | I13: R3 | J13: I | K13: Utiliser des outils pour réaliser une tâche concrète avec précision. | L13: Cela ne m’attire pas du tout | M13: Cela m’attire peu | N13: Je suis partagé(e) / sans préférence marquée | O13: Cela m’attire | P13: Cela m’attire beaucoup | Q13: 1 | R13: 2 | S13: 3 | T13: 4 | U13: 5 | V13: La formulation cible l’intérêt pour action concrète sur le réel et résultat tangible. Elle mobilise un comportement caractéristique de la dimension R (Réaliste) sans demander un niveau de compétence préalable. | W13: L’item relève de R3 — Outils / machines / équipements : Usage direct d’outils, machines, instruments ou équipements techniques. | X13: Revue méthodologique V0.3 : surveiller projection en cas de limitation physique ou sensorielle, familiarité avec le contexte professionnel au pilote. | Y13: FAIBLE | Z13: FAIBLE | AA13: FAIBLE | AB13: FAIBLE | AC13: FAIBLE | AD13: MOYEN | AE13: FAIBLE | AF13: FAIBLE | AG13: MOYEN | AH13: FAIBLE | AI13: FAIBLE | AJ13: 0 | AL13: RETENU_V0.5_REECRIT_CONCRET | AN13: PIP-BANK-0.3 | AO13: PIP-BANK-0.4 | AP13: =IF(OR(C13="PILOTE",C13="ACTIF"),IF(AND(A13<>"",H13<>"",I13<>"",K13<>"",V13<>"",W13<>""),"OK","A_COMPLETER"),"OK_STRUCTURE")
A14: PIP-ACT-R-R3-010 | B14: 0.2 | C14: PILOTE | D14: 08/09/2026 | E14: 08/09/2026 | F14: ACT | G14: Verbe d’action + objet/contexte | H14: R | I14: R3 | J14: I | K14: Piloter ou régler une machine pour obtenir le résultat attendu. | L14: Cela ne m’attire pas du tout | M14: Cela m’attire peu | N14: Je suis partagé(e) / sans préférence marquée | O14: Cela m’attire | P14: Cela m’attire beaucoup | Q14: 1 | R14: 2 | S14: 3 | T14: 4 | U14: 5 | V14: La formulation cible l’intérêt pour action concrète sur le réel et résultat tangible. Elle mobilise un comportement caractéristique de la dimension R (Réaliste) sans demander un niveau de compétence préalable. | W14: L’item relève de R3 — Outils / machines / équipements : Usage direct d’outils, machines, instruments ou équipements techniques. | X14: Revue méthodologique V0.3 : surveiller projection en cas de limitation physique ou sensorielle, familiarité avec le contexte professionnel au pilote. | Y14: FAIBLE | Z14: FAIBLE | AA14: FAIBLE | AB14: FAIBLE | AC14: FAIBLE | AD14: MOYEN | AE14: FAIBLE | AF14: FAIBLE | AG14: MOYEN | AH14: FAIBLE | AI14: FAIBLE | AJ14: 0 | AL14: RETENU_V0.5_REECRIT_CONCRET | AN14: PIP-BANK-0.3 | AO14: PIP-BANK-0.4 | AP14: =IF(OR(C14="PILOTE",C14="ACTIF"),IF(AND(A14<>"",H14<>"",I14<>"",K14<>"",V14<>"",W14<>""),"OK","A_COMPLETER"),"OK_STRUCTURE")
A15: PIP-SIT-R-R3-011 | B15: 0.2 | C15: PILOTE | D15: 08/09/2026 | E15: 08/09/2026 | F15: SIT | G15: Situation courte avec enjeu central | H15: R | I15: R3 | J15: I | K15: Prendre en charge une tâche qui nécessite de manipuler directement un appareil ou un équipement. | L15: Cela ne m’attire pas du tout | M15: Cela m’attire peu | N15: Je suis partagé(e) / sans préférence marquée | O15: Cela m’attire | P15: Cela m’attire beaucoup | Q15: 1 | R15: 2 | S15: 3 | T15: 4 | U15: 5 | V15: La formulation cible l’intérêt pour action concrète sur le réel et résultat tangible. Elle mobilise un comportement caractéristique de la dimension R (Réaliste) sans demander un niveau de compétence préalable. | W15: L’item relève de R3 — Outils / machines / équipements : Usage direct d’outils, machines, instruments ou équipements techniques. | X15: Revue méthodologique V0.3 : surveiller projection en cas de limitation physique ou sensorielle, familiarité avec le contexte professionnel au pilote. | Y15: FAIBLE | Z15: FAIBLE | AA15: FAIBLE | AB15: FAIBLE | AC15: FAIBLE | AD15: MOYEN | AE15: FAIBLE | AF15: FAIBLE | AG15: MOYEN | AH15: FAIBLE | AI15: FAIBLE | AJ15: 0 | AL15: RETENU_V0.5_REECRIT_CONCRET | AN15: PIP-BANK-0.3 | AO15: PIP-BANK-0.4 | AP15: =IF(OR(C15="PILOTE",C15="ACTIF"),IF(AND(A15<>"",H15<>"",I15<>"",K15<>"",V15<>"",W15<>""),"OK","A_COMPLETER"),"OK_STRUCTURE")
A16: PIP-ENV-R-R3-012 | B16: 0.2 | C16: PILOTE | D16: 08/09/2026 | E16: 08/09/2026 | F16: ENV | G16: Contexte décrit par ce qu’il permet de faire | H16: R | I16: R3 | J16: I | K16: Travailler dans un environnement où l’on utilise régulièrement des outils, des instruments ou des machines pour agir sur le réel. | L16: Cela ne m’attire pas du tout | M16: Cela m’attire peu | N16: Je suis partagé(e) / sans préférence marquée | O16: Cela m’attire | P16: Cela m’attire beaucoup | Q16: 1 | R16: 2 | S16: 3 | T16: 4 | U16: 5 | V16: La formulation cible l’intérêt pour action concrète sur le réel et résultat tangible. Elle mobilise un comportement caractéristique de la dimension R (Réaliste) sans demander un niveau de compétence préalable. | W16: L’item relève de R3 — Outils / machines / équipements : Usage direct d’outils, machines, instruments ou équipements techniques. | X16: Revue méthodologique V0.3 : surveiller projection en cas de limitation physique ou sensorielle, familiarité avec le contexte professionnel au pilote. | Y16: FAIBLE | Z16: FAIBLE | AA16: FAIBLE | AB16: FAIBLE | AC16: FAIBLE | AD16: MOYEN | AE16: FAIBLE | AF16: FAIBLE | AG16: MOYEN | AH16: FAIBLE | AI16: FAIBLE | AJ16: 0 | AL16: RETIRE_BANQUE72_HISTORIQUE_CONSERVE | AM16: Réduction méthodologique 120→72 : doublon de facette / priorité aux activités professionnelles observables et aux items à plus faible risque. | AN16: PIP-BANK-0.3 | AO16: PIP-BANK-0.3 | AP16: =IF(OR(C16="PILOTE",C16="ACTIF"),IF(AND(A16<>"",H16<>"",I16<>"",K16<>"",V16<>"",W16<>""),"OK","A_COMPLETER"),"OK_STRUCTURE")
A17: PIP-ACT-R-R4-013 | B17: 0.2 | C17: PILOTE | D17: 08/09/2026 | E17: 08/09/2026 | F17: ACT | G17: Verbe d’action + objet/contexte | H17: R | I17: R4 | J17: I | K17: Se rendre sur différents sites pour intervenir directement sur le terrain. | L17: Cela ne m’attire pas du tout | M17: Cela m’attire peu | N17: Je suis partagé(e) / sans préférence marquée | O17: Cela m’attire | P17: Cela m’attire beaucoup | Q17: 1 | R17: 2 | S17: 3 | T17: 4 | U17: 5 | V17: La formulation cible l’intérêt pour action concrète sur le réel et résultat tangible. Elle mobilise un comportement caractéristique de la dimension R (Réaliste) sans demander un niveau de compétence préalable. | W17: L’item relève de R4 — Terrain / environnement concret : Action dans des contextes physiques, extérieurs ou directement liés à un environnement réel. | X17: Revue méthodologique V0.3 : surveiller projection en cas de limitation physique ou sensorielle, familiarité avec le contexte professionnel au pilote. | Y17: FAIBLE | Z17: FAIBLE | AA17: FAIBLE | AB17: FAIBLE | AC17: FAIBLE | AD17: MOYEN | AE17: FAIBLE | AF17: FAIBLE | AG17: MOYEN | AH17: FAIBLE | AI17: FAIBLE | AJ17: 0 | AL17: RETENU_V0.5_REECRIT_CONCRET | AN17: PIP-BANK-0.3 | AO17: PIP-BANK-0.4 | AP17: =IF(OR(C17="PILOTE",C17="ACTIF"),IF(AND(A17<>"",H17<>"",I17<>"",K17<>"",V17<>"",W17<>""),"OK","A_COMPLETER"),"OK_STRUCTURE")
A18: PIP-ACT-R-R4-014 | B18: 0.2 | C18: PILOTE | D18: 08/09/2026 | E18: 08/09/2026 | F18: ACT | G18: Verbe d’action + objet/contexte | H18: R | I18: R4 | J18: I | K18: Réaliser une activité professionnelle principalement en extérieur. | L18: Cela ne m’attire pas du tout | M18: Cela m’attire peu | N18: Je suis partagé(e) / sans préférence marquée | O18: Cela m’attire | P18: Cela m’attire beaucoup | Q18: 1 | R18: 2 | S18: 3 | T18: 4 | U18: 5 | V18: La formulation cible l’intérêt pour action concrète sur le réel et résultat tangible. Elle mobilise un comportement caractéristique de la dimension R (Réaliste) sans demander un niveau de compétence préalable. | W18: L’item relève de R4 — Terrain / environnement concret : Action dans des contextes physiques, extérieurs ou directement liés à un environnement réel. | X18: Revue méthodologique V0.3 : surveiller projection en cas de limitation physique ou sensorielle, familiarité avec le contexte professionnel au pilote. | Y18: FAIBLE | Z18: FAIBLE | AA18: FAIBLE | AB18: FAIBLE | AC18: FAIBLE | AD18: MOYEN | AE18: FAIBLE | AF18: FAIBLE | AG18: MOYEN | AH18: FAIBLE | AI18: FAIBLE | AJ18: 0 | AL18: RETENU_V0.5_REECRIT_CONCRET | AN18: PIP-BANK-0.3 | AO18: PIP-BANK-0.4 | AP18: =IF(OR(C18="PILOTE",C18="ACTIF"),IF(AND(A18<>"",H18<>"",I18<>"",K18<>"",V18<>"",W18<>""),"OK","A_COMPLETER"),"OK_STRUCTURE")
A19: PIP-SIT-R-R4-015 | B19: 0.2 | C19: PILOTE | D19: 08/09/2026 | E19: 08/09/2026 | F19: SIT | G19: Situation courte avec enjeu central | H19: R | I19: R4 | J19: I | K19: Intervenir sur place lorsqu’une situation concrète doit être traitée directement plutôt qu’à distance. | L19: Cela ne m’attire pas du tout | M19: Cela m’attire peu | N19: Je suis partagé(e) / sans préférence marquée | O19: Cela m’attire | P19: Cela m’attire beaucoup | Q19: 1 | R19: 2 | S19: 3 | T19: 4 | U19: 5 | V19: La formulation cible l’intérêt pour action concrète sur le réel et résultat tangible. Elle mobilise un comportement caractéristique de la dimension R (Réaliste) sans demander un niveau de compétence préalable. | W19: L’item relève de R4 — Terrain / environnement concret : Action dans des contextes physiques, extérieurs ou directement liés à un environnement réel. | X19: Revue méthodologique V0.3 : surveiller projection en cas de limitation physique ou sensorielle, familiarité avec le contexte professionnel au pilote. | Y19: FAIBLE | Z19: FAIBLE | AA19: FAIBLE | AB19: FAIBLE | AC19: FAIBLE | AD19: MOYEN | AE19: FAIBLE | AF19: FAIBLE | AG19: MOYEN | AH19: FAIBLE | AI19: FAIBLE | AJ19: 0 | AL19: RETIRE_BANQUE72_HISTORIQUE_CONSERVE | AM19: Réduction méthodologique 120→72 : doublon de facette / priorité aux activités professionnelles observables et aux items à plus faible risque. | AN19: PIP-BANK-0.3 | AO19: PIP-BANK-0.3 | AP19: =IF(OR(C19="PILOTE",C19="ACTIF"),IF(AND(A19<>"",H19<>"",I19<>"",K19<>"",V19<>"",W19<>""),"OK","A_COMPLETER"),"OK_STRUCTURE")
A20: PIP-ENV-R-R4-016 | B20: 0.2 | C20: PILOTE | D20: 08/09/2026 | E20: 08/09/2026 | F20: ENV | G20: Contexte décrit par ce qu’il permet de faire | H20: R | I20: R4 | J20: I | K20: Travailler dans un contexte où l’activité se déroule souvent sur le terrain, au contact direct de l’environnement réel. | L20: Cela ne m’attire pas du tout | M20: Cela m’attire peu | N20: Je suis partagé(e) / sans préférence marquée | O20: Cela m’attire | P20: Cela m’attire beaucoup | Q20: 1 | R20: 2 | S20: 3 | T20: 4 | U20: 5 | V20: La formulation cible l’intérêt pour action concrète sur le réel et résultat tangible. Elle mobilise un comportement caractéristique de la dimension R (Réaliste) sans demander un niveau de compétence préalable. | W20: L’item relève de R4 — Terrain / environnement concret : Action dans des contextes physiques, extérieurs ou directement liés à un environnement réel. | X20: Revue méthodologique V0.3 : surveiller projection en cas de limitation physique ou sensorielle, familiarité avec le contexte professionnel au pilote. | Y20: FAIBLE | Z20: FAIBLE | AA20: FAIBLE | AB20: FAIBLE | AC20: FAIBLE | AD20: MOYEN | AE20: FAIBLE | AF20: FAIBLE | AG20: MOYEN | AH20: FAIBLE | AI20: FAIBLE | AJ20: 0 | AL20: RETIRE_BANQUE72_HISTORIQUE_CONSERVE | AM20: Réduction méthodologique 120→72 : doublon de facette / priorité aux activités professionnelles observables et aux items à plus faible risque. | AN20: PIP-BANK-0.3 | AO20: PIP-BANK-0.3 | AP20: =IF(OR(C20="PILOTE",C20="ACTIF"),IF(AND(A20<>"",H20<>"",I20<>"",K20<>"",V20<>"",W20<>""),"OK","A_COMPLETER"),"OK_STRUCTURE")
